Workbook

Sheet Gesamt_Auswertung
B1: Tesseract | K1: Engine | L1: Dataset | M1: Metric | N1: Value
A2: Textabschnitte | C2: PT(s) | D2: OldBooks300dpi | F2: PT(s) | G2: OldBooks500dpi | I2: PT(s) | K2: Tesseract | L2: Textabschnitte | M2: CER | N2: =tesseract_textabschnitte!$A$5486 -> 0.21553972
A3: CER | B3: WER | D3: CER | E3: WER | G3: CER | H3: WER | K3: Tesseract | L3: Textabschnitte | M3: WER | N3: =tesseract_textabschnitte!$B$5486 -> 0.28288745
A4: =tesseract_textabschnitte!$A$5486 -> 0.21553972 | B4: =tesseract_textabschnitte!$B$5486 -> 0.28288745 | C4: =tesseract_textabschnitte!$C$2 -> 621.81 | D4: =tesseract_oldbooks300dpi!$A$325 -> 0.020093781 | E4: =tesseract_oldbooks300dpi!$B$325 -> 0.056498306 | F4: =tesseract_oldbooks300dpi!$C$2 -> 238.12 | G4: =tesseract_oldbooks500dpi!$A$325 -> 0.022971264 | H4: =tesseract_oldbooks500dpi!$B$325 -> 0.062407357 | I4: =tesseract_oldbooks500dpi!$C$2 -> 371.38 | K4: Tesseract | L4: Textabschnitte | M4: PT(s) | N4: =tesseract_textabschnitte!$C$2 -> 621.81
K5: Tesseract | L5: OldBooks300dpi | M5: CER | N5: =tesseract_oldbooks300dpi!$A$325 -> 0.020093781
B6: PaddleOCR | K6: Tesseract | L6: OldBooks300dpi | M6: WER | N6: =tesseract_oldbooks300dpi!$B$325 -> 0.056498306
A7: Textabschnitte | C7: PT(s) | D7: OldBooks300dpi | F7: PT(s) | G7: OldBooks500dpi | I7: PT(s) | K7: Tesseract | L7: OldBooks300dpi | M7: PT(s) | N7: =tesseract_oldbooks300dpi!$C$2 -> 238.12
A8: CER | B8: WER | D8: CER | E8: WER | G8: CER | H8: WER | K8: Tesseract | L8: OldBooks500dpi | M8: CER | N8: =tesseract_oldbooks500dpi!$A$325 -> 0.022971264
A9: =paddle_textabschnitte!$A$5486 -> 0.3030713 | B9: =paddle_textabschnitte!$B$5486 -> 0.47386628 | C9: =paddle_textabschnitte!$C$2 -> 5246.14 | D9: =paddle_oldbooks300dpi!$A$325 -> 0.17875933 | E9: =paddle_oldbooks300dpi!$B$325 -> 0.27039937 | F9: =paddle_oldbooks300dpi!$C$2 -> 2394.97 | G9: =paddle_oldbooks500dpi!$A$325 -> 0.33434535 | H9: =paddle_oldbooks500dpi!$B$325 -> 0.45899747 | I9: =paddle_oldbooks500dpi!$C$2 -> 5396.76 | K9: Tesseract | L9: OldBooks500dpi | M9: WER | N9: =tesseract_oldbooks500dpi!$B$325 -> 0.062407357
K10: Tesseract | L10: OldBooks500dpi | M10: PT(s) | N10: =tesseract_oldbooks500dpi!$C$2 -> 371.38
B11: EasyOCR | K11: PaddleOCR | L11: Textabschnitte | M11: CER | N11: =paddle_textabschnitte!$A$5486 -> 0.3030713
A12: Textabschnitte | C12: PT(s) | D12: OldBooks300dpi | F12: PT(s) | G12: OldBooks500dpi | I12: PT(s) | K12: PaddleOCR | L12: Textabschnitte | M12: WER | N12: =paddle_textabschnitte!$B$5486 -> 0.47386628
A13: CER | B13: WER | D13: CER | E13: WER | G13: CER | H13: WER | K13: PaddleOCR | L13: Textabschnitte | M13: PT(s) | N13: =paddle_textabschnitte!$C$2 -> 5246.14
A14: =easyocr_textabschnitte!$A$5478 -> 0.088368065 | B14: =easyocr_textabschnitte!$B$5478 -> 0.18546584 | C14: =easyocr_textabschnitte!$C$2 -> 627.10 | D14: =easyocr_oldbooks300dpi!$A$325 -> 0.075985619 | E14: =easyocr_oldbooks300dpi!$B$325 -> 0.18544072 | F14: =easyocr_oldbooks300dpi!$C$2 -> 2665.66 | G14: =easyocr_oldbooks500dpi!$A$325 -> 0.075241071 | H14: =easyocr_oldbooks500dpi!$B$325 -> 0.18090034 | I14: =easyocr_oldbooks500dpi!$C$2 -> 3225.75 | K14: PaddleOCR | L14: OldBooks300dpi | M14: CER | N14: =paddle_oldbooks300dpi!$A$325 -> 0.17875933
K15: PaddleOCR | L15: OldBooks300dpi | M15: WER | N15: =paddle_oldbooks300dpi!$B$325 -> 0.27039937
B16: DeepseekOCR | K16: PaddleOCR | L16: OldBooks300dpi | M16: PT(s) | N16: =paddle_oldbooks300dpi!$C$2 -> 2394.97
A17: Textabschnitte | C17: PT(s) | D17: OldBooks300dpi | F17: PT(s) | G17: OldBooks500dpi | I17: PT(s) | K17: PaddleOCR | L17: OldBooks500dpi | M17: CER | N17: =paddle_oldbooks500dpi!$A$325 -> 0.33434535
A18: CER | B18: WER | D18: CER | E18: WER | G18: CER | H18: WER | K18: PaddleOCR | L18: OldBooks500dpi | M18: WER | N18: =paddle_oldbooks500dpi!$B$325 -> 0.45899747
A19: =deepseek_textabschnitte!$A$5486 -> 0.12709012 | B19: =deepseek_textabschnitte!$B$5486 -> 0.1721676 | C19: =deepseek_textabschnitte!$C$2 -> 7738.97 | D19: =deepseek_oldbooks300dpi!$A$325 -> 0.028942836 | E19: =deepseek_oldbooks300dpi!$B$325 -> 0.042914499 | F19: =deepseek_oldbooks300dpi!$C$2 -> 5217.73 | G19: =deepseek_oldbooks500dpi!$A$325 -> 0.029605354 | H19: =deepseek_oldbooks500dpi!$B$325 -> 0.043431661 | I19: =deepseek_oldbooks500dpi!$C$2 -> 3867.80 | K19: PaddleOCR | L19: OldBooks500dpi | M19: PT(s) | N19: =paddle_oldbooks500dpi!$C$2 -> 5396.76
K20: EasyOCR | L20: Textabschnitte | M20: CER | N20: =easyocr_textabschnitte!$A$5478 -> 0.088368065
B21: GoogleCloudVision | K21: EasyOCR | L21: Textabschnitte | M21: WER | N21: =easyocr_textabschnitte!$B$5478 -> 0.18546584
A22: Textabschnitte | C22: PT(s) | D22: OldBooks300dpi | F22: PT(s) | G22: OldBooks500dpi | I22: PT(s) | K22: EasyOCR | L22: Textabschnitte | M22: PT(s) | N22: =easyocr_textabschnitte!$C$2 -> 627.10
A23: CER | B23: WER | D23: CER | E23: WER | G23: CER | H23: WER | K23: EasyOCR | L23: OldBooks300dpi | M23: CER | N23: =easyocr_oldbooks300dpi!$A$325 -> 0.075985619
A24: =cloudvision_textabschnitte!$A$5486 -> 0.028882016 | B24: =cloudvision_textabschnitte!$B$5486 -> 0.06430329 | C24: =cloudvision_textabschnitte!$C$2 -> 1161.01 | D24: =cloudvision_oldbooks300dpi!$A$325 -> 0.017237865 | E24: =cloudvision_oldbooks300dpi!$B$325 -> 0.039146889 | F24: =cloudvision_oldbooks300dpi!$C$2 -> 813.29 | G24: =cloudvision_oldbooks500dpi!$A$317 -> 0.016236174 | H24: =cloudvision_oldbooks500dpi!$B$317 -> 0.037893551 | I24: =cloudvision_oldbooks500dpi!$C$2 -> 2129.50 | K24: EasyOCR | L24: OldBooks300dpi | M24: WER | N24: =easyocr_oldbooks300dpi!$B$325 -> 0.18544072
K25: EasyOCR | L25: OldBooks300dpi | M25: PT(s) | N25: =easyocr_oldbooks300dpi!$C$2 -> 2665.66
K26: EasyOCR | L26: OldBooks500dpi | M26: CER | N26: =easyocr_oldbooks500dpi!$A$325 -> 0.075241071
K27: EasyOCR | L27: OldBooks500dpi | M27: WER | N27: =easyocr_oldbooks500dpi!$B$325 -> 0.18090034
K28: EasyOCR | L28: OldBooks500dpi | M28: PT(s) | N28: =easyocr_oldbooks500dpi!$C$2 -> 3225.75
K29: DeepseekOCR | L29: Textabschnitte | M29: CER | N29: =deepseek_textabschnitte!$A$5486 -> 0.12709012
K30: DeepseekOCR | L30: Textabschnitte | M30: WER | N30: =deepseek_textabschnitte!$B$5486 -> 0.1721676
K31: DeepseekOCR | L31: Textabschnitte | M31: PT(s) | N31: =deepseek_textabschnitte!$C$2 -> 7738.97
K32: DeepseekOCR | L32: OldBooks300dpi | M32: CER | N32: =deepseek_oldbooks300dpi!$A$325 -> 0.028942836
K33: DeepseekOCR | L33: OldBooks300dpi | M33: WER | N33: =deepseek_oldbooks300dpi!$B$325 -> 0.042914499
K34: DeepseekOCR | L34: OldBooks300dpi | M34: PT(s) | N34: =deepseek_oldbooks300dpi!$C$2 -> 5217.73
K35: DeepseekOCR | L35: OldBooks500dpi | M35: CER | N35: =deepseek_oldbooks500dpi!$A$325 -> 0.029605354
K36: DeepseekOCR | L36: OldBooks500dpi | M36: WER | N36: =deepseek_oldbooks500dpi!$B$325 -> 0.043431661
K37: DeepseekOCR | L37: OldBooks500dpi | M37: PT(s) | N37: =deepseek_oldbooks500dpi!$C$2 -> 3867.80
K38: GoogleCloudVision | L38: Textabschnitte | M38: CER | N38: =cloudvision_textabschnitte!$A$5486 -> 0.028882016
K39: GoogleCloudVision | L39: Textabschnitte | M39: WER | N39: =cloudvision_textabschnitte!$B$5486 -> 0.06430329
K40: GoogleCloudVision | L40: Textabschnitte | M40: PT(s) | N40: =cloudvision_textabschnitte!$C$2 -> 1161.01
...

Sheet tesseract_textabschnitte
A1: cer | B1: wer | C1: Total OCR processing time: seconds
A2: 0 | B2: 0 | C2: 621.81
A3: 0.66666667 | B3: 1
A4: 0 | B4: 0
A5: 0 | B5: 0
A6: 1 | B6: 1
A7: 0.032258065 | B7: 0.2
A8: 0 | B8: 0
A9: 0 | B9: 0
A10: 0.125 | B10: 1
A11: 0 | B11: 0
A12: 0 | B12: 0
A13: 1 | B13: 1
A14: 0 | B14: 0
... A5484: 1 | B5484: 1
A5486: =AVERAGE(A2:A5484) -> 0.21553972 | B5486: =AVERAGE(B2:B5484) -> 0.28288745

Sheet tesseract_oldbooks300dpi
A1: cer | B1: wer | C1: Total OCR processing time: seconds
A2: 0.016689847 | B2: 0.087719298 | C2: 238.12
A3: 0.0054141852 | B3: 0.042763158
A4: 0.050847458 | B4: 0.10191083
A5: 0.14355231 | B5: 0.1937799
A6: 0.0066298343 | B6: 0.043478261
A7: 0.017408124 | B7: 0.069767442
A8: 0.004456328 | B8: 0.034739454
A9: 0.0046395432 | B9: 0.036072144
A10: 0.0043763676 | B10: 0.029978587
A11: 0.0018691589 | B11: 0.011037528
A12: 0.005841548 | B12: 0.043103448
A13: 0.016405396 | B13: 0.085057471
A14: 0.0058159425 | B14: 0.024948025
... A323: 0.0020366599 | B323: 0.0053191489
A325: =AVERAGE(A2:A323) -> 0.020093781 | B325: =AVERAGE(B2:B323) -> 0.056498306

Sheet tesseract_oldbooks500dpi
A1: cer | B1: wer | C1: Total OCR processing time: seconds
A2: 0.052851182 | B2: 0.20175439 | C2: 371.38
A3: 0.0081212777 | B3: 0.029605263
A4: 0.050847458 | B4: 0.11464968
A5: 0.13665856 | B5: 0.18421053
A6: 0.0077348066 | B6: 0.052173913
A7: 0.023210832 | B7: 0.081395349
A8: 0.0080213904 | B8: 0.044665012
A9: 0.0046395432 | B9: 0.036072144
A10: 0.0051057622 | B10: 0.038543897
A11: 0.0059813084 | B11: 0.028697572
A12: 0.0083972253 | B12: 0.051724138
A13: 0.015676267 | B13: 0.07816092
A14: 0.0047895997 | B14: 0.027027027
... A323: 0.0010183299 | B323: 0.0053191489
A325: =AVERAGE(A2:A323) -> 0.022971264 | B325: =AVERAGE(B2:B323) -> 0.062407357

Sheet easyocr_textabschnitte
A1: cer | B1: wer | C1: Total OCR processing time: seconds
A2: 0 | B2: 0 | C2: 627.10
A3: 0 | B3: 0 | F3: [WARN] Skipping 1282.tiff: not a TIFF file b'\x89PNG'
A4: 0.125 | B4: 1 | F4: [WARN] Skipping 1319.tiff: <COMPRESSION.LZW: 5> requires the 'imagecodecs' package
A5: 0 | B5: 0 | F5: [WARN] Skipping 1439.tiff: <COMPRESSION.LZW: 5> requires the 'imagecodecs' package
A6: 0 | B6: 0 | F6: [WARN] Skipping 1578.tiff: <COMPRESSION.LZW: 5> requires the 'imagecodecs' package
A7: 0.096774194 | B7: 0.4 | F7: [WARN] Skipping 1579.tiff: <COMPRESSION.LZW: 5> requires the 'imagecodecs' package
A8: 0 | B8: 0 | F8: [WARN] Skipping 1580.tiff: <COMPRESSION.LZW: 5> requires the 'imagecodecs' package
A9: 0.33333333 | B9: 1 | F9: [WARN] Skipping 1581.tiff: <COMPRESSION.LZW: 5> requires the 'imagecodecs' package
A10: 0 | B10: 0 | F10: [WARN] Skipping Template24_1408.tiff: not a TIFF file b'\xff\xd8\xff\xe0'
A11: 0 | B11: 0
A12: 0 | B12: 0
A13: 0.5 | B13: 1
A14: 0 | B14: 0
A15: 0 | B15: 0
A16: 0.16666667 | B16: 1
A17: 0.66666667 | B17: 1
A18: 0 | B18: 0
A19: 0.25 | B19: 0.5
A20: 0.33333333 | B20: 1
A21: 0.032258065 | B21: 0.25
A22: 0 | B22: 0
... A5476: 0 | B5476: 0
A5478: =AVERAGE(A2:A5476) -> 0.088368065 | B5478: =AVERAGE(B2:B5476) -> 0.18546584

Sheet easyocr_oldbooks300dpi
A1: cer | B1: wer | C1: Total OCR processing time: seconds
A2: 0.055632823 | B2: 0.23684211 | C2: 2665.66
A3: 0.10449377 | B3: 0.21381579
A4: 0.34596211 | B4: 0.57961783
A5: 0.27696675 | B5: 0.47368421
A6: 0.10202578 | B6: 0.3
A7: 0.040618956 | B7: 0.1744186
A8: 0.056595365 | B8: 0.1439206
A9: 0.065310493 | B9: 0.16032064
A10: 0.067833698 | B10: 0.16702355
A11: 0.065046729 | B11: 0.13245033
A12: 0.067542899 | B12: 0.20043103
A13: 0.10973387 | B13: 0.30114943
A14: 0.091002395 | B14: 0.22245322
... A323: 0.048879837 | B323: 0.11170213
A325: =AVERAGE(A2:A323) -> 0.075985619 | B325: =AVERAGE(B2:B323) -> 0.18544072

Sheet easyocr_oldbooks500dpi
A1: cer | B1: wer | C1: Total OCR processing time: seconds
A2: 0.04867872 | B2: 0.21052632 | C2: 3225.75
A3: 0.10016243 | B3: 0.19736842
A4: 0.34695912 | B4: 0.54140127
A5: 0.27210057 | B5: 0.44258373
A6: 0.095764273 | B6: 0.27826087
A7: 0.032882012 | B7: 0.13953488
A8: 0.040998217 | B8: 0.13151365
A9: 0.056031406 | B9: 0.15831663
A10: 0.057986871 | B10: 0.14775161
A11: 0.049719626 | B11: 0.11699779
A12: 0.079956188 | B12: 0.19181034
A13: 0.09733868 | B13: 0.28965517
A14: 0.088607595 | B14: 0.2037422
... A323: 0.044806517 | B323: 0.15425532
A325: =AVERAGE(A2:A323) -> 0.075241071 | B325: =AVERAGE(B2:B323) -> 0.18090034

Sheet paddle_textabschnitte
A1: cer | B1: wer | C1: Total OCR processing time: seconds
A2: 0.97058824 | B2: 1 | C2: 5246.14
A3: 0.33333333 | B3: 1
A4: 0 | B4: 0
A5: 0 | B5: 0
A6: 0 | B6: 0
A7: 0 | B7: 0
A8: 0 | B8: 0
A9: 0 | B9: 0
A10: 0 | B10: 0
A11: 0 | B11: 0
A12: 0 | B12: 0
A13: 1 | B13: 1
A14: 0 | B14: 0
... A5484: 1 | B5484: 1
A5486: =AVERAGE(A2:A5484) -> 0.3030713 | B5486: =AVERAGE(B2:B5484) -> 0.47386628

Sheet paddle_oldbooks300dpi
A1: cer | B1: wer | C1: Total OCR processing time: seconds
A2: 0.031988873 | B2: 0.14035088 | C2: 2394.97
A3: 0.034109367 | B3: 0.098684211
A4: 0.45663011 | B4: 0.58598726
A5: 0.32278994 | B5: 0.45933014
A6: 0.15911602 | B6: 0.26521739
A7: 0.059961315 | B7: 0.18604651
A8: 0.21167558 | B8: 0.33498759
A9: 0.19022127 | B9: 0.26853707
A10: 0.33223924 | B10: 0.43254818
A11: 0.11439252 | B11: 0.21633554
A12: 0.1683096 | B12: 0.26293103
A13: 0.2770689 | B13: 0.4137931
A14: 0.27984947 | B14: 0.41372141
... A323: 0.046843177 | B323: 0.058510638
A325: =AVERAGE(A2:A323) -> 0.17875933 | B325: =AVERAGE(B2:B323) -> 0.27039937

Sheet paddle_oldbooks500dpi
A1: cer | B1: wer | C1: Total OCR processing time: seconds
A2: 0.18636996 | B2: 0.34210526 | C2: 5396.76
A3: 0.13210612 | B3: 0.26644737
A4: 0.7108674 | B4: 0.91082803
A5: 0.47120843 | B5: 0.62200957
A6: 0.36132597 | B6: 0.54347826
A7: 1 | B7: 1
A8: 0.36853832 | B8: 0.48138958
A9: 0.32655246 | B9: 0.4749499
A10: 0.47228301 | B10: 0.65738758
A11: 0.26915888 | B11: 0.401766
A12: 0.33150785 | B12: 0.46551724
A13: 0.44221655 | B13: 0.64367816
A14: 0.44338009 | B14: 0.58419958
... A323: 0.19348269 | B323: 0.23404255
A325: =AVERAGE(A2:A323) -> 0.33434535 | B325: =AVERAGE(B2:B323) -> 0.45899747

Sheet deepseek_textabschnitte
A1: cer | B1: wer | C1: Total OCR processing time: seconds
A2: 0 | B2: 0 | C2: 7738.97
A3: 0.66666667 | B3: 1
A4: 0 | B4: 0
A5: 0 | B5: 0
A6: 0 | B6: 0
A7: 0.032258065 | B7: 0.2
A8: 0 | B8: 0
A9: 0 | B9: 0
A10: 0 | B10: 0
A11: 0 | B11: 0
A12: 0 | B12: 0
A13: 0.5 | B13: 1
A14: 0 | B14: 0
... A5484: 0 | B5484: 0
A5486: =AVERAGE(A2:A5484) -> 0.12709012 | B5486: =AVERAGE(B2:B5484) -> 0.1721676

Sheet deepseek_oldbooks300dpi
A1: cer | B1: wer | C1: Total OCR processing time: seconds
A2: 0.0055632823 | B2: 0.035087719 | C2: 5217.73
A3: 0.0048727666 | B3: 0.019736842
A4: 0.03888335 | B4: 0.050955414
A5: 0.14111922 | B5: 0.16507177
A6: 0.0044198895 | B6: 0.02173913
A7: 0.013539652 | B7: 0.058139535
A8: 0.002228164 | B8: 0.0099255583
A9: 0.0053533191 | B9: 0.024048096
A10: 0.0051057622 | B10: 0.025695931
A11: 0.0026168224 | B11: 0.011037528
A12: 0.004381161 | B12: 0.017241379
A13: 0.012759752 | B13: 0.062068966
A14: 0.0037632569 | B14: 0.016632017
... A323: 0.052953157 | B323: 0.053191489
A325: =AVERAGE(A2:A323) -> 0.028942836 | B325: =AVERAGE(B2:B323) -> 0.042914499

Sheet deepseek_oldbooks500dpi
A1: cer | B1: wer | C1: Total OCR processing time: seconds
A2: 0.0055632823 | B2: 0.035087719 | C2: 3867.80
A3: 0.0027070926 | B3: 0.0065789474
A4: 0.03888335 | B4: 0.050955414
A5: 0.13990268 | B5: 0.15789474
A6: 0.0033149171 | B6: 0.017391304
A7: 0.013539652 | B7: 0.058139535
A8: 0.002228164 | B8: 0.0099255583
A9: 0.0053533191 | B9: 0.024048096
A10: 0.0051057622 | B10: 0.025695931
A11: 0.0026168224 | B11: 0.011037528
A12: 0.0069368383 | B12: 0.023706897
A13: 0.012759752 | B13: 0.062068966
A14: 0.0041053712 | B14: 0.018711019
... A323: 0.052953157 | B323: 0.053191489
A325: =AVERAGE(A2:A323) -> 0.029605354 | B325: =AVERAGE(B2:B323) -> 0.043431661

Sheet cloudvision_textabschnitte
A1: cer | B1: wer | C1: Total OCR processing time: seconds
A2: 0 | B2: 0 | C2: 1161.01
A3: 0.33333333 | B3: 1
A4: 0 | B4: 0
A5: 0 | B5: 0
A6: 0 | B6: 0
A7: 0.032258065 | B7: 0.2
A8: 0 | B8: 0
A9: 0 | B9: 0
A10: 0 | B10: 0
A11: 0 | B11: 0
A12: 0 | B12: 0
A13: 0.5 | B13: 1
A14: 0 | B14: 0
... A5484: 0 | B5484: 0
A5486: =AVERAGE(A2:A5484) -> 0.028882016 | B5486: =AVERAGE(B2:B5484) -> 0.06430329

Sheet cloudvision_oldbooks300dpi
A1: cer | B1: wer | C1: Total OCR processing time: seconds
A2: 0.0097357441 | B2: 0.043859649 | C2: 813.29
A3: 0.0048727666 | B3: 0.029605263
A4: 0.23529412 | B4: 0.24840764
A5: 0.14193025 | B5: 0.16507177
A6: 0.0022099448 | B6: 0.010869565
A7: 0.015473888 | B7: 0.069767442
A8: 0.002228164 | B8: 0.0099255583
A9: 0.0085653105 | B9: 0.028056112
A10: 0.0043763676 | B10: 0.025695931
A11: 0.0011214953 | B11: 0.0066225166
A12: 0.0036509675 | B12: 0.017241379
A13: 0.014947138 | B13: 0.073563218
A14: 0.0027369141 | B14: 0.016632017
... A323: 0.0030549898 | B323: 0.015957447
A325: =AVERAGE(A2:A323) -> 0.017237865 | B325: =AVERAGE(B2:B323) -> 0.039146889

Sheet cloudvision_oldbooks500dpi
A1: cer | B1: wer | C1: Total OCR processing time: seconds
A2: 0.012517385 | B2: 0.061403509 | C2: 2129.50
A3: 0.0048727666 | B3: 0.026315789
A4: 0.24925224 | B4: 0.25477707 | D4: C:\Users\Daniel\PycharmProjects\Thesis_OCR_Bench\.venv\Scripts\python.exe C:\Users\Daniel\PycharmProjects\Thesis_OCR_Bench\ocr_google.py
A5: 0.14193025 | B5: 0.16985646 | D5: [WARN] Skipping b013.tiff: 400 Request payload size exceeds the limit: 41943040 bytes.
A6: 0.0033149171 | B6: 0.017391304 | D6: [WARN] Skipping b014.tiff: 400 Request payload size exceeds the limit: 41943040 bytes.
A7: 0.017408124 | B7: 0.081395349 | D7: [WARN] Skipping b017.tiff: 400 Request payload size exceeds the limit: 41943040 bytes.
A8: 0.0026737968 | B8: 0.012406948 | D8: [WARN] Skipping b018.tiff: 400 Request payload size exceeds the limit: 41943040 bytes.
A9: 0.0085653105 | B9: 0.03006012 | D9: [WARN] Skipping b027.tiff: 400 Request payload size exceeds the limit: 41943040 bytes.
A10: 0.0040116703 | B10: 0.021413276 | D10: [WARN] Skipping b028.tiff: 400 Request payload size exceeds the limit: 41943040 bytes.
A11: 0.0014953271 | B11: 0.0088300221 | D11: [WARN] Skipping b029.tiff: 400 Request payload size exceeds the limit: 41943040 bytes.
A12: 0.002920774 | B12: 0.012931034 | D12: [WARN] Skipping b030.tiff: 400 Request payload size exceeds the limit: 41943040 bytes.
A13: 0.011301495 | B13: 0.062068966 | D13: OCR (Google Cloud Vision) complete.
A14: 0.0034211427 | B14: 0.020790021 | D14: Total OCR processing time: 2129.50 seconds
A15: 0.0017378352 | B15: 0.010130246 | D15: Processing time saved to: C:\Users\Daniel\PycharmProjects\Thesis_OCR_Bench\ocr_google.txt
A16: 0.0083160083 | B16: 0.036585366
A17: 0.0021208908 | B17: 0.012820513 | D17: Process finished with exit code 0
A18: 0.0041400075 | B18: 0.025404157
A19: 0.0018867925 | B19: 0.011764706
A20: 0.011861314 | B20: 0.02739726
A21: 0.0018436578 | B21: 0.015384615
A22: 0.0039167687 | B22: 0.023703704
A23: 0.0032987747 | B23: 0.016806723
A24: 0.011258278 | B24: 0.025423729
A25: 0.0057827344 | B25: 0.031100478
A26: 0.0040396621 | B26: 0.016736402
A27: 0.0018691589 | B27: 0.012526096
A28: 0.0052083333 | B28: 0.031941032
A29: 0.065598398 | B29: 0.066666667
... A315: 0.0050916497 | B315: 0.026595745
A317: =AVERAGE(A2:A315) -> 0.016236174 | B317: =AVERAGE(B2:B315) -> 0.037893551
